<<<<<<< HEAD
2025-06-25 09:56:05,197-INFO-sales data extraction started....
2025-06-25 09:56:05,199-ERROR-Error encounted while extrcting the sales data file,[Errno 2] No such file or directory: 'SourceSystems/sales_data_Linux_remot.csv'
Traceback (most recent call last):
  File "D:\Capstone_Apr_Batch_Development\CodeBase\extract.py", line 21, in extract_sales_data_from_file
    df = pd.read_csv("SourceSystems/sales_data_Linux_remot.csv")
  File "C:\Python310\lib\site-packages\pandas\io\parsers\readers.py", line 948, in read_csv
    return _read(filepath_or_buffer, kwds)
  File "C:\Python310\lib\site-packages\pandas\io\parsers\readers.py", line 611, in _read
    parser = TextFileReader(filepath_or_buffer, **kwds)
  File "C:\Python310\lib\site-packages\pandas\io\parsers\readers.py", line 1448, in __init__
    self._engine = self._make_engine(f, self.engine)
  File "C:\Python310\lib\site-packages\pandas\io\parsers\readers.py", line 1705, in _make_engine
    self.handles = get_handle(
  File "C:\Python310\lib\site-packages\pandas\io\common.py", line 863, in get_handle
    handle = open(
FileNotFoundError: [Errno 2] No such file or directory: 'SourceSystems/sales_data_Linux_remot.csv'
2025-06-25 09:56:05,199-INFO-product data extraction started....
2025-06-25 09:56:05,199-ERROR-Error encounted while extrcting the product data file,[Errno 2] No such file or directory: 'SourceSystems/product_data.cs'
Traceback (most recent call last):
  File "D:\Capstone_Apr_Batch_Development\CodeBase\extract.py", line 31, in extract_product_data_from_file
    df = pd.read_csv("SourceSystems/product_data.cs")
  File "C:\Python310\lib\site-packages\pandas\io\parsers\readers.py", line 948, in read_csv
    return _read(filepath_or_buffer, kwds)
  File "C:\Python310\lib\site-packages\pandas\io\parsers\readers.py", line 611, in _read
    parser = TextFileReader(filepath_or_buffer, **kwds)
  File "C:\Python310\lib\site-packages\pandas\io\parsers\readers.py", line 1448, in __init__
    self._engine = self._make_engine(f, self.engine)
  File "C:\Python310\lib\site-packages\pandas\io\parsers\readers.py", line 1705, in _make_engine
    self.handles = get_handle(
  File "C:\Python310\lib\site-packages\pandas\io\common.py", line 863, in get_handle
    handle = open(
FileNotFoundError: [Errno 2] No such file or directory: 'SourceSystems/product_data.cs'
2025-06-25 09:56:05,199-INFO-supplier data extraction started....
2025-06-25 09:56:05,529-INFO-supplier data extraction completed....
2025-06-25 09:56:05,529-INFO-inventory data extraction started....
2025-06-25 09:56:05,897-INFO-inventory data extraction completed....
2025-06-25 09:56:05,897-INFO-stores data extraction started....
2025-06-25 09:56:06,753-INFO-stores data extraction completed....
2025-06-26 00:24:13,847-INFO-sales data extraction started....
2025-06-26 00:24:13,882-ERROR-Error encounted while extrcting the sales data file,[Errno 2] No such file or directory: 'Capstone_Apr25_Batch_development/SourceSystems/sales_data_Linux_remote.csv'
Traceback (most recent call last):
  File "F:\Software Testing\ETL Automation with Python\Project\PythonProject\Capstone_Apr25_Batch_development\CodeBase\extract.py", line 22, in extract_sales_data_from_file
    df = pd.read_csv("Capstone_Apr25_Batch_development/SourceSystems/sales_data_Linux_remote.csv")
         ^^^^^^^^^^^^^^^^^^^^^^^^^^^^^^^^^^^^^^^^^^^^^^^^^^^^^^^^^^^^^^^^^^^^^^^^^^^^^^^^^^^^^^^^^
  File "F:\Software Testing\ETL Automation with Python\Project\PythonProject\.venv\Lib\site-packages\pandas\io\parsers\readers.py", line 1026, in read_csv
    return _read(filepath_or_buffer, kwds)
           ^^^^^^^^^^^^^^^^^^^^^^^^^^^^^^^
  File "F:\Software Testing\ETL Automation with Python\Project\PythonProject\.venv\Lib\site-packages\pandas\io\parsers\readers.py", line 620, in _read
    parser = TextFileReader(filepath_or_buffer, **kwds)
             ^^^^^^^^^^^^^^^^^^^^^^^^^^^^^^^^^^^^^^^^^^
  File "F:\Software Testing\ETL Automation with Python\Project\PythonProject\.venv\Lib\site-packages\pandas\io\parsers\readers.py", line 1620, in __init__
    self._engine = self._make_engine(f, self.engine)
                   ^^^^^^^^^^^^^^^^^^^^^^^^^^^^^^^^^
  File "F:\Software Testing\ETL Automation with Python\Project\PythonProject\.venv\Lib\site-packages\pandas\io\parsers\readers.py", line 1880, in _make_engine
    self.handles = get_handle(
                   ^^^^^^^^^^^
  File "F:\Software Testing\ETL Automation with Python\Project\PythonProject\.venv\Lib\site-packages\pandas\io\common.py", line 873, in get_handle
    handle = open(
             ^^^^^
FileNotFoundError: [Errno 2] No such file or directory: 'Capstone_Apr25_Batch_development/SourceSystems/sales_data_Linux_remote.csv'
2025-06-26 00:24:13,916-INFO-product data extraction started....
2025-06-26 00:24:13,916-ERROR-Error encounted while extrcting the product data file,[Errno 2] No such file or directory: 'Capstone_Apr25_Batch_development/SourceSystems/product_data.csv'
Traceback (most recent call last):
  File "F:\Software Testing\ETL Automation with Python\Project\PythonProject\Capstone_Apr25_Batch_development\CodeBase\extract.py", line 32, in extract_product_data_from_file
    df = pd.read_csv("Capstone_Apr25_Batch_development/SourceSystems/product_data.csv")
         ^^^^^^^^^^^^^^^^^^^^^^^^^^^^^^^^^^^^^^^^^^^^^^^^^^^^^^^^^^^^^^^^^^^^^^^^^^^^^^
  File "F:\Software Testing\ETL Automation with Python\Project\PythonProject\.venv\Lib\site-packages\pandas\io\parsers\readers.py", line 1026, in read_csv
    return _read(filepath_or_buffer, kwds)
           ^^^^^^^^^^^^^^^^^^^^^^^^^^^^^^^
  File "F:\Software Testing\ETL Automation with Python\Project\PythonProject\.venv\Lib\site-packages\pandas\io\parsers\readers.py", line 620, in _read
    parser = TextFileReader(filepath_or_buffer, **kwds)
             ^^^^^^^^^^^^^^^^^^^^^^^^^^^^^^^^^^^^^^^^^^
  File "F:\Software Testing\ETL Automation with Python\Project\PythonProject\.venv\Lib\site-packages\pandas\io\parsers\readers.py", line 1620, in __init__
    self._engine = self._make_engine(f, self.engine)
                   ^^^^^^^^^^^^^^^^^^^^^^^^^^^^^^^^^
  File "F:\Software Testing\ETL Automation with Python\Project\PythonProject\.venv\Lib\site-packages\pandas\io\parsers\readers.py", line 1880, in _make_engine
    self.handles = get_handle(
                   ^^^^^^^^^^^
  File "F:\Software Testing\ETL Automation with Python\Project\PythonProject\.venv\Lib\site-packages\pandas\io\common.py", line 873, in get_handle
    handle = open(
             ^^^^^
FileNotFoundError: [Errno 2] No such file or directory: 'Capstone_Apr25_Batch_development/SourceSystems/product_data.csv'
2025-06-26 00:24:13,918-INFO-supplier data extraction started....
2025-06-26 00:24:13,918-ERROR-Error encounted while extrcting the supplier data file,File Capstone_Apr25_Batch_development/SourceSystems/supplier_data.json does not exist
Traceback (most recent call last):
  File "F:\Software Testing\ETL Automation with Python\Project\PythonProject\Capstone_Apr25_Batch_development\CodeBase\extract.py", line 42, in extract_supplier_data_from_file
    df = pd.read_json("Capstone_Apr25_Batch_development/SourceSystems/supplier_data.json")
         ^^^^^^^^^^^^^^^^^^^^^^^^^^^^^^^^^^^^^^^^^^^^^^^^^^^^^^^^^^^^^^^^^^^^^^^^^^^^^^^^^
  File "F:\Software Testing\ETL Automation with Python\Project\PythonProject\.venv\Lib\site-packages\pandas\io\json\_json.py", line 791, in read_json
    json_reader = JsonReader(
                  ^^^^^^^^^^^
  File "F:\Software Testing\ETL Automation with Python\Project\PythonProject\.venv\Lib\site-packages\pandas\io\json\_json.py", line 904, in __init__
    data = self._get_data_from_filepath(filepath_or_buffer)
           ^^^^^^^^^^^^^^^^^^^^^^^^^^^^^^^^^^^^^^^^^^^^^^^^
  File "F:\Software Testing\ETL Automation with Python\Project\PythonProject\.venv\Lib\site-packages\pandas\io\json\_json.py", line 960, in _get_data_from_filepath
    raise FileNotFoundError(f"File {filepath_or_buffer} does not exist")
FileNotFoundError: File Capstone_Apr25_Batch_development/SourceSystems/supplier_data.json does not exist
2025-06-26 00:24:13,925-INFO-inventory data extraction started....
2025-06-26 00:24:13,929-ERROR-Error encounted while extrcting the inventory data file,lxml not found, please install or use the etree parser.
Traceback (most recent call last):
  File "F:\Software Testing\ETL Automation with Python\Project\PythonProject\Capstone_Apr25_Batch_development\CodeBase\extract.py", line 51, in extract_inventory_data_from_file
    df = pd.read_xml("Capstone_Apr25_Batch_development/SourceSystems/inventory_data.xml",xpath=".//item")
         ^^^^^^^^^^^^^^^^^^^^^^^^^^^^^^^^^^^^^^^^^^^^^^^^^^^^^^^^^^^^^^^^^^^^^^^^^^^^^^^^^^^^^^^^^^^^^^^^
  File "F:\Software Testing\ETL Automation with Python\Project\PythonProject\.venv\Lib\site-packages\pandas\io\xml.py", line 1160, in read_xml
    return _parse(
           ^^^^^^^
  File "F:\Software Testing\ETL Automation with Python\Project\PythonProject\.venv\Lib\site-packages\pandas\io\xml.py", line 830, in _parse
    raise ImportError("lxml not found, please install or use the etree parser.")
ImportError: lxml not found, please install or use the etree parser.
2025-06-26 00:24:13,931-INFO-stores data extraction started....
2025-06-26 00:24:14,940-INFO-stores data extraction completed....
2025-06-26 00:30:19,048-INFO-sales data extraction started....
2025-06-26 00:30:19,051-ERROR-Error encounted while extrcting the sales data file,[Errno 2] No such file or directory: 'Capstone_Apr25_Batch_development/SourceSystems/sales_data_Linux_remote.csv'
Traceback (most recent call last):
  File "F:\Software Testing\ETL Automation with Python\Project\PythonProject\Capstone_Apr25_Batch_development\CodeBase\extract.py", line 24, in extract_sales_data_from_file
    df = pd.read_csv("Capstone_Apr25_Batch_development/SourceSystems/sales_data_Linux_remote.csv")
         ^^^^^^^^^^^^^^^^^^^^^^^^^^^^^^^^^^^^^^^^^^^^^^^^^^^^^^^^^^^^^^^^^^^^^^^^^^^^^^^^^^^^^^^^^
  File "F:\Software Testing\ETL Automation with Python\Project\PythonProject\.venv\Lib\site-packages\pandas\io\parsers\readers.py", line 1026, in read_csv
    return _read(filepath_or_buffer, kwds)
           ^^^^^^^^^^^^^^^^^^^^^^^^^^^^^^^
  File "F:\Software Testing\ETL Automation with Python\Project\PythonProject\.venv\Lib\site-packages\pandas\io\parsers\readers.py", line 620, in _read
    parser = TextFileReader(filepath_or_buffer, **kwds)
             ^^^^^^^^^^^^^^^^^^^^^^^^^^^^^^^^^^^^^^^^^^
  File "F:\Software Testing\ETL Automation with Python\Project\PythonProject\.venv\Lib\site-packages\pandas\io\parsers\readers.py", line 1620, in __init__
    self._engine = self._make_engine(f, self.engine)
                   ^^^^^^^^^^^^^^^^^^^^^^^^^^^^^^^^^
  File "F:\Software Testing\ETL Automation with Python\Project\PythonProject\.venv\Lib\site-packages\pandas\io\parsers\readers.py", line 1880, in _make_engine
    self.handles = get_handle(
                   ^^^^^^^^^^^
  File "F:\Software Testing\ETL Automation with Python\Project\PythonProject\.venv\Lib\site-packages\pandas\io\common.py", line 873, in get_handle
    handle = open(
             ^^^^^
FileNotFoundError: [Errno 2] No such file or directory: 'Capstone_Apr25_Batch_development/SourceSystems/sales_data_Linux_remote.csv'
2025-06-26 00:30:19,054-INFO-product data extraction started....
2025-06-26 00:30:19,054-ERROR-Error encounted while extrcting the product data file,[Errno 2] No such file or directory: 'Capstone_Apr25_Batch_development/SourceSystems/product_data.csv'
Traceback (most recent call last):
  File "F:\Software Testing\ETL Automation with Python\Project\PythonProject\Capstone_Apr25_Batch_development\CodeBase\extract.py", line 34, in extract_product_data_from_file
    df = pd.read_csv("Capstone_Apr25_Batch_development/SourceSystems/product_data.csv")
         ^^^^^^^^^^^^^^^^^^^^^^^^^^^^^^^^^^^^^^^^^^^^^^^^^^^^^^^^^^^^^^^^^^^^^^^^^^^^^^
  File "F:\Software Testing\ETL Automation with Python\Project\PythonProject\.venv\Lib\site-packages\pandas\io\parsers\readers.py", line 1026, in read_csv
    return _read(filepath_or_buffer, kwds)
           ^^^^^^^^^^^^^^^^^^^^^^^^^^^^^^^
  File "F:\Software Testing\ETL Automation with Python\Project\PythonProject\.venv\Lib\site-packages\pandas\io\parsers\readers.py", line 620, in _read
    parser = TextFileReader(filepath_or_buffer, **kwds)
             ^^^^^^^^^^^^^^^^^^^^^^^^^^^^^^^^^^^^^^^^^^
  File "F:\Software Testing\ETL Automation with Python\Project\PythonProject\.venv\Lib\site-packages\pandas\io\parsers\readers.py", line 1620, in __init__
    self._engine = self._make_engine(f, self.engine)
                   ^^^^^^^^^^^^^^^^^^^^^^^^^^^^^^^^^
  File "F:\Software Testing\ETL Automation with Python\Project\PythonProject\.venv\Lib\site-packages\pandas\io\parsers\readers.py", line 1880, in _make_engine
    self.handles = get_handle(
                   ^^^^^^^^^^^
  File "F:\Software Testing\ETL Automation with Python\Project\PythonProject\.venv\Lib\site-packages\pandas\io\common.py", line 873, in get_handle
    handle = open(
             ^^^^^
FileNotFoundError: [Errno 2] No such file or directory: 'Capstone_Apr25_Batch_development/SourceSystems/product_data.csv'
2025-06-26 00:30:19,056-INFO-supplier data extraction started....
2025-06-26 00:30:19,056-ERROR-Error encounted while extrcting the supplier data file,File Capstone_Apr25_Batch_development/SourceSystems/supplier_data.json does not exist
Traceback (most recent call last):
  File "F:\Software Testing\ETL Automation with Python\Project\PythonProject\Capstone_Apr25_Batch_development\CodeBase\extract.py", line 44, in extract_supplier_data_from_file
    df = pd.read_json("Capstone_Apr25_Batch_development/SourceSystems/supplier_data.json")
         ^^^^^^^^^^^^^^^^^^^^^^^^^^^^^^^^^^^^^^^^^^^^^^^^^^^^^^^^^^^^^^^^^^^^^^^^^^^^^^^^^
  File "F:\Software Testing\ETL Automation with Python\Project\PythonProject\.venv\Lib\site-packages\pandas\io\json\_json.py", line 791, in read_json
    json_reader = JsonReader(
                  ^^^^^^^^^^^
  File "F:\Software Testing\ETL Automation with Python\Project\PythonProject\.venv\Lib\site-packages\pandas\io\json\_json.py", line 904, in __init__
    data = self._get_data_from_filepath(filepath_or_buffer)
           ^^^^^^^^^^^^^^^^^^^^^^^^^^^^^^^^^^^^^^^^^^^^^^^^
  File "F:\Software Testing\ETL Automation with Python\Project\PythonProject\.venv\Lib\site-packages\pandas\io\json\_json.py", line 960, in _get_data_from_filepath
    raise FileNotFoundError(f"File {filepath_or_buffer} does not exist")
FileNotFoundError: File Capstone_Apr25_Batch_development/SourceSystems/supplier_data.json does not exist
2025-06-26 00:30:19,057-INFO-inventory data extraction started....
2025-06-26 00:30:19,059-ERROR-Error encounted while extrcting the inventory data file,lxml not found, please install or use the etree parser.
Traceback (most recent call last):
  File "F:\Software Testing\ETL Automation with Python\Project\PythonProject\Capstone_Apr25_Batch_development\CodeBase\extract.py", line 53, in extract_inventory_data_from_file
    df = pd.read_xml("Capstone_Apr25_Batch_development/SourceSystems/inventory_data.xml",xpath=".//item")
         ^^^^^^^^^^^^^^^^^^^^^^^^^^^^^^^^^^^^^^^^^^^^^^^^^^^^^^^^^^^^^^^^^^^^^^^^^^^^^^^^^^^^^^^^^^^^^^^^
  File "F:\Software Testing\ETL Automation with Python\Project\PythonProject\.venv\Lib\site-packages\pandas\io\xml.py", line 1160, in read_xml
    return _parse(
           ^^^^^^^
  File "F:\Software Testing\ETL Automation with Python\Project\PythonProject\.venv\Lib\site-packages\pandas\io\xml.py", line 830, in _parse
    raise ImportError("lxml not found, please install or use the etree parser.")
ImportError: lxml not found, please install or use the etree parser.
2025-06-26 00:30:19,060-INFO-stores data extraction started....
2025-06-26 00:30:19,259-INFO-stores data extraction completed....
2025-06-26 00:34:20,844-INFO-sales data extraction started....
2025-06-26 00:34:20,846-ERROR-Error encounted while extrcting the sales data file,[Errno 2] No such file or directory: 'Capstone_Apr25_Batch_development/SourceSystems/sales_data_Linux_remote.csv'
Traceback (most recent call last):
  File "F:\Software Testing\ETL Automation with Python\Project\PythonProject\Capstone_Apr25_Batch_development\CodeBase\extract.py", line 24, in extract_sales_data_from_file
    df = pd.read_csv("Capstone_Apr25_Batch_development/SourceSystems/sales_data_Linux_remote.csv")
         ^^^^^^^^^^^^^^^^^^^^^^^^^^^^^^^^^^^^^^^^^^^^^^^^^^^^^^^^^^^^^^^^^^^^^^^^^^^^^^^^^^^^^^^^^
  File "F:\Software Testing\ETL Automation with Python\Project\PythonProject\.venv\Lib\site-packages\pandas\io\parsers\readers.py", line 1026, in read_csv
    return _read(filepath_or_buffer, kwds)
           ^^^^^^^^^^^^^^^^^^^^^^^^^^^^^^^
  File "F:\Software Testing\ETL Automation with Python\Project\PythonProject\.venv\Lib\site-packages\pandas\io\parsers\readers.py", line 620, in _read
    parser = TextFileReader(filepath_or_buffer, **kwds)
             ^^^^^^^^^^^^^^^^^^^^^^^^^^^^^^^^^^^^^^^^^^
  File "F:\Software Testing\ETL Automation with Python\Project\PythonProject\.venv\Lib\site-packages\pandas\io\parsers\readers.py", line 1620, in __init__
    self._engine = self._make_engine(f, self.engine)
                   ^^^^^^^^^^^^^^^^^^^^^^^^^^^^^^^^^
  File "F:\Software Testing\ETL Automation with Python\Project\PythonProject\.venv\Lib\site-packages\pandas\io\parsers\readers.py", line 1880, in _make_engine
    self.handles = get_handle(
                   ^^^^^^^^^^^
  File "F:\Software Testing\ETL Automation with Python\Project\PythonProject\.venv\Lib\site-packages\pandas\io\common.py", line 873, in get_handle
    handle = open(
             ^^^^^
FileNotFoundError: [Errno 2] No such file or directory: 'Capstone_Apr25_Batch_development/SourceSystems/sales_data_Linux_remote.csv'
2025-06-26 00:34:20,849-INFO-product data extraction started....
2025-06-26 00:34:20,850-ERROR-Error encounted while extrcting the product data file,[Errno 2] No such file or directory: 'Capstone_Apr25_Batch_development/SourceSystems/product_data.csv'
Traceback (most recent call last):
  File "F:\Software Testing\ETL Automation with Python\Project\PythonProject\Capstone_Apr25_Batch_development\CodeBase\extract.py", line 34, in extract_product_data_from_file
    df = pd.read_csv("Capstone_Apr25_Batch_development/SourceSystems/product_data.csv")
         ^^^^^^^^^^^^^^^^^^^^^^^^^^^^^^^^^^^^^^^^^^^^^^^^^^^^^^^^^^^^^^^^^^^^^^^^^^^^^^
  File "F:\Software Testing\ETL Automation with Python\Project\PythonProject\.venv\Lib\site-packages\pandas\io\parsers\readers.py", line 1026, in read_csv
    return _read(filepath_or_buffer, kwds)
           ^^^^^^^^^^^^^^^^^^^^^^^^^^^^^^^
  File "F:\Software Testing\ETL Automation with Python\Project\PythonProject\.venv\Lib\site-packages\pandas\io\parsers\readers.py", line 620, in _read
    parser = TextFileReader(filepath_or_buffer, **kwds)
             ^^^^^^^^^^^^^^^^^^^^^^^^^^^^^^^^^^^^^^^^^^
  File "F:\Software Testing\ETL Automation with Python\Project\PythonProject\.venv\Lib\site-packages\pandas\io\parsers\readers.py", line 1620, in __init__
    self._engine = self._make_engine(f, self.engine)
                   ^^^^^^^^^^^^^^^^^^^^^^^^^^^^^^^^^
  File "F:\Software Testing\ETL Automation with Python\Project\PythonProject\.venv\Lib\site-packages\pandas\io\parsers\readers.py", line 1880, in _make_engine
    self.handles = get_handle(
                   ^^^^^^^^^^^
  File "F:\Software Testing\ETL Automation with Python\Project\PythonProject\.venv\Lib\site-packages\pandas\io\common.py", line 873, in get_handle
    handle = open(
             ^^^^^
FileNotFoundError: [Errno 2] No such file or directory: 'Capstone_Apr25_Batch_development/SourceSystems/product_data.csv'
2025-06-26 00:34:20,851-INFO-supplier data extraction started....
2025-06-26 00:34:20,851-ERROR-Error encounted while extrcting the supplier data file,File Capstone_Apr25_Batch_development/SourceSystems/supplier_data.json does not exist
Traceback (most recent call last):
  File "F:\Software Testing\ETL Automation with Python\Project\PythonProject\Capstone_Apr25_Batch_development\CodeBase\extract.py", line 44, in extract_supplier_data_from_file
    df = pd.read_json("Capstone_Apr25_Batch_development/SourceSystems/supplier_data.json")
         ^^^^^^^^^^^^^^^^^^^^^^^^^^^^^^^^^^^^^^^^^^^^^^^^^^^^^^^^^^^^^^^^^^^^^^^^^^^^^^^^^
  File "F:\Software Testing\ETL Automation with Python\Project\PythonProject\.venv\Lib\site-packages\pandas\io\json\_json.py", line 791, in read_json
    json_reader = JsonReader(
                  ^^^^^^^^^^^
  File "F:\Software Testing\ETL Automation with Python\Project\PythonProject\.venv\Lib\site-packages\pandas\io\json\_json.py", line 904, in __init__
    data = self._get_data_from_filepath(filepath_or_buffer)
           ^^^^^^^^^^^^^^^^^^^^^^^^^^^^^^^^^^^^^^^^^^^^^^^^
  File "F:\Software Testing\ETL Automation with Python\Project\PythonProject\.venv\Lib\site-packages\pandas\io\json\_json.py", line 960, in _get_data_from_filepath
    raise FileNotFoundError(f"File {filepath_or_buffer} does not exist")
FileNotFoundError: File Capstone_Apr25_Batch_development/SourceSystems/supplier_data.json does not exist
2025-06-26 00:34:20,853-INFO-inventory data extraction started....
2025-06-26 00:34:20,854-ERROR-Error encounted while extrcting the inventory data file,lxml not found, please install or use the etree parser.
Traceback (most recent call last):
  File "F:\Software Testing\ETL Automation with Python\Project\PythonProject\Capstone_Apr25_Batch_development\CodeBase\extract.py", line 54, in extract_inventory_data_from_file
    df = pd.read_xml(xml_file, xpath=".//item")
         ^^^^^^^^^^^^^^^^^^^^^^^^^^^^^^^^^^^^^^
  File "F:\Software Testing\ETL Automation with Python\Project\PythonProject\.venv\Lib\site-packages\pandas\io\xml.py", line 1160, in read_xml
    return _parse(
           ^^^^^^^
  File "F:\Software Testing\ETL Automation with Python\Project\PythonProject\.venv\Lib\site-packages\pandas\io\xml.py", line 830, in _parse
    raise ImportError("lxml not found, please install or use the etree parser.")
ImportError: lxml not found, please install or use the etree parser.
2025-06-26 00:34:20,854-INFO-stores data extraction started....
2025-06-26 00:34:20,993-INFO-stores data extraction completed....
2025-06-26 00:40:46,252-INFO-sales data extraction started....
2025-06-26 00:40:46,255-ERROR-Error encounted while extrcting the sales data file,[Errno 2] No such file or directory: 'Capstone_Apr25_Batch_development/SourceSystems/sales_data_Linux_remote.csv'
Traceback (most recent call last):
  File "F:\Software Testing\ETL Automation with Python\Project\PythonProject\Capstone_Apr25_Batch_development\CodeBase\extract.py", line 24, in extract_sales_data_from_file
    df = pd.read_csv("Capstone_Apr25_Batch_development/SourceSystems/sales_data_Linux_remote.csv")
         ^^^^^^^^^^^^^^^^^^^^^^^^^^^^^^^^^^^^^^^^^^^^^^^^^^^^^^^^^^^^^^^^^^^^^^^^^^^^^^^^^^^^^^^^^
  File "F:\Software Testing\ETL Automation with Python\Project\PythonProject\.venv\Lib\site-packages\pandas\io\parsers\readers.py", line 1026, in read_csv
    return _read(filepath_or_buffer, kwds)
           ^^^^^^^^^^^^^^^^^^^^^^^^^^^^^^^
  File "F:\Software Testing\ETL Automation with Python\Project\PythonProject\.venv\Lib\site-packages\pandas\io\parsers\readers.py", line 620, in _read
    parser = TextFileReader(filepath_or_buffer, **kwds)
             ^^^^^^^^^^^^^^^^^^^^^^^^^^^^^^^^^^^^^^^^^^
  File "F:\Software Testing\ETL Automation with Python\Project\PythonProject\.venv\Lib\site-packages\pandas\io\parsers\readers.py", line 1620, in __init__
    self._engine = self._make_engine(f, self.engine)
                   ^^^^^^^^^^^^^^^^^^^^^^^^^^^^^^^^^
  File "F:\Software Testing\ETL Automation with Python\Project\PythonProject\.venv\Lib\site-packages\pandas\io\parsers\readers.py", line 1880, in _make_engine
    self.handles = get_handle(
                   ^^^^^^^^^^^
  File "F:\Software Testing\ETL Automation with Python\Project\PythonProject\.venv\Lib\site-packages\pandas\io\common.py", line 873, in get_handle
    handle = open(
             ^^^^^
FileNotFoundError: [Errno 2] No such file or directory: 'Capstone_Apr25_Batch_development/SourceSystems/sales_data_Linux_remote.csv'
2025-06-26 00:40:46,286-INFO-product data extraction started....
2025-06-26 00:40:46,286-ERROR-Error encounted while extrcting the product data file,[Errno 2] No such file or directory: 'Capstone_Apr25_Batch_development/SourceSystems/product_data.csv'
Traceback (most recent call last):
  File "F:\Software Testing\ETL Automation with Python\Project\PythonProject\Capstone_Apr25_Batch_development\CodeBase\extract.py", line 34, in extract_product_data_from_file
    df = pd.read_csv("Capstone_Apr25_Batch_development/SourceSystems/product_data.csv")
         ^^^^^^^^^^^^^^^^^^^^^^^^^^^^^^^^^^^^^^^^^^^^^^^^^^^^^^^^^^^^^^^^^^^^^^^^^^^^^^
  File "F:\Software Testing\ETL Automation with Python\Project\PythonProject\.venv\Lib\site-packages\pandas\io\parsers\readers.py", line 1026, in read_csv
    return _read(filepath_or_buffer, kwds)
           ^^^^^^^^^^^^^^^^^^^^^^^^^^^^^^^
  File "F:\Software Testing\ETL Automation with Python\Project\PythonProject\.venv\Lib\site-packages\pandas\io\parsers\readers.py", line 620, in _read
    parser = TextFileReader(filepath_or_buffer, **kwds)
             ^^^^^^^^^^^^^^^^^^^^^^^^^^^^^^^^^^^^^^^^^^
  File "F:\Software Testing\ETL Automation with Python\Project\PythonProject\.venv\Lib\site-packages\pandas\io\parsers\readers.py", line 1620, in __init__
    self._engine = self._make_engine(f, self.engine)
                   ^^^^^^^^^^^^^^^^^^^^^^^^^^^^^^^^^
  File "F:\Software Testing\ETL Automation with Python\Project\PythonProject\.venv\Lib\site-packages\pandas\io\parsers\readers.py", line 1880, in _make_engine
    self.handles = get_handle(
                   ^^^^^^^^^^^
  File "F:\Software Testing\ETL Automation with Python\Project\PythonProject\.venv\Lib\site-packages\pandas\io\common.py", line 873, in get_handle
    handle = open(
             ^^^^^
FileNotFoundError: [Errno 2] No such file or directory: 'Capstone_Apr25_Batch_development/SourceSystems/product_data.csv'
2025-06-26 00:40:46,287-INFO-supplier data extraction started....
2025-06-26 00:40:46,288-ERROR-Error encounted while extrcting the supplier data file,File Capstone_Apr25_Batch_development/SourceSystems/supplier_data.json does not exist
Traceback (most recent call last):
  File "F:\Software Testing\ETL Automation with Python\Project\PythonProject\Capstone_Apr25_Batch_development\CodeBase\extract.py", line 44, in extract_supplier_data_from_file
    df = pd.read_json("Capstone_Apr25_Batch_development/SourceSystems/supplier_data.json")
         ^^^^^^^^^^^^^^^^^^^^^^^^^^^^^^^^^^^^^^^^^^^^^^^^^^^^^^^^^^^^^^^^^^^^^^^^^^^^^^^^^
  File "F:\Software Testing\ETL Automation with Python\Project\PythonProject\.venv\Lib\site-packages\pandas\io\json\_json.py", line 791, in read_json
    json_reader = JsonReader(
                  ^^^^^^^^^^^
  File "F:\Software Testing\ETL Automation with Python\Project\PythonProject\.venv\Lib\site-packages\pandas\io\json\_json.py", line 904, in __init__
    data = self._get_data_from_filepath(filepath_or_buffer)
           ^^^^^^^^^^^^^^^^^^^^^^^^^^^^^^^^^^^^^^^^^^^^^^^^
  File "F:\Software Testing\ETL Automation with Python\Project\PythonProject\.venv\Lib\site-packages\pandas\io\json\_json.py", line 960, in _get_data_from_filepath
    raise FileNotFoundError(f"File {filepath_or_buffer} does not exist")
FileNotFoundError: File Capstone_Apr25_Batch_development/SourceSystems/supplier_data.json does not exist
2025-06-26 00:40:46,296-INFO-inventory data extraction started....
2025-06-26 00:40:46,297-ERROR-Error encounted while extrcting the inventory data file,lxml not found, please install or use the etree parser.
Traceback (most recent call last):
  File "F:\Software Testing\ETL Automation with Python\Project\PythonProject\Capstone_Apr25_Batch_development\CodeBase\extract.py", line 54, in extract_inventory_data_from_file
    df = pd.read_xml(xml_file, xpath=".//item")
         ^^^^^^^^^^^^^^^^^^^^^^^^^^^^^^^^^^^^^^
  File "F:\Software Testing\ETL Automation with Python\Project\PythonProject\.venv\Lib\site-packages\pandas\io\xml.py", line 1160, in read_xml
    return _parse(
           ^^^^^^^
  File "F:\Software Testing\ETL Automation with Python\Project\PythonProject\.venv\Lib\site-packages\pandas\io\xml.py", line 830, in _parse
    raise ImportError("lxml not found, please install or use the etree parser.")
ImportError: lxml not found, please install or use the etree parser.
2025-06-26 00:40:46,298-INFO-stores data extraction started....
2025-06-26 00:40:46,572-INFO-stores data extraction completed....
2025-06-26 00:43:40,368-INFO-sales data extraction started....
2025-06-26 00:43:40,516-INFO-sales data extraction completed....
2025-06-26 00:43:40,516-INFO-product data extraction started....
2025-06-26 00:43:40,595-INFO-product data extraction completed....
2025-06-26 00:43:40,595-INFO-supplier data extraction started....
2025-06-26 00:43:40,715-INFO-supplier data extraction completed....
2025-06-26 00:43:40,715-INFO-inventory data extraction started....
2025-06-26 00:43:40,716-ERROR-Error encounted while extrcting the inventory data file,lxml not found, please install or use the etree parser.
Traceback (most recent call last):
  File "F:\Software Testing\ETL Automation with Python\Project\PythonProject\Capstone_Apr25_Batch_development\CodeBase\extract.py", line 54, in extract_inventory_data_from_file
    df = pd.read_xml(xml_file, xpath=".//item")
         ^^^^^^^^^^^^^^^^^^^^^^^^^^^^^^^^^^^^^^
  File "F:\Software Testing\ETL Automation with Python\Project\PythonProject\.venv\Lib\site-packages\pandas\io\xml.py", line 1160, in read_xml
    return _parse(
           ^^^^^^^
  File "F:\Software Testing\ETL Automation with Python\Project\PythonProject\.venv\Lib\site-packages\pandas\io\xml.py", line 830, in _parse
    raise ImportError("lxml not found, please install or use the etree parser.")
ImportError: lxml not found, please install or use the etree parser.
2025-06-26 00:43:40,717-INFO-stores data extraction started....
2025-06-26 00:43:40,827-INFO-stores data extraction completed....
2025-06-26 00:47:52,734-INFO-sales data extraction started....
2025-06-26 00:47:52,858-INFO-sales data extraction completed....
2025-06-26 00:47:52,858-INFO-product data extraction started....
2025-06-26 00:47:52,926-INFO-product data extraction completed....
2025-06-26 00:47:52,926-INFO-supplier data extraction started....
2025-06-26 00:47:53,017-INFO-supplier data extraction completed....
2025-06-26 00:47:53,018-INFO-inventory data extraction started....
2025-06-26 00:47:53,019-ERROR-Error encounted while extrcting the inventory data file,lxml not found, please install or use the etree parser.
Traceback (most recent call last):
  File "F:\Software Testing\ETL Automation with Python\Project\PythonProject\Capstone_Apr25_Batch_development\CodeBase\extract.py", line 54, in extract_inventory_data_from_file
    df = pd.read_xml(xml_file, xpath=".//item")
         ^^^^^^^^^^^^^^^^^^^^^^^^^^^^^^^^^^^^^^
  File "F:\Software Testing\ETL Automation with Python\Project\PythonProject\.venv\Lib\site-packages\pandas\io\xml.py", line 1160, in read_xml
    return _parse(
           ^^^^^^^
  File "F:\Software Testing\ETL Automation with Python\Project\PythonProject\.venv\Lib\site-packages\pandas\io\xml.py", line 830, in _parse
    raise ImportError("lxml not found, please install or use the etree parser.")
ImportError: lxml not found, please install or use the etree parser.
2025-06-26 00:47:53,021-INFO-stores data extraction started....
2025-06-26 00:47:53,153-INFO-stores data extraction completed....
2025-06-26 00:50:54,321-INFO-sales data extraction started....
2025-06-26 00:50:54,410-INFO-sales data extraction completed....
2025-06-26 00:50:54,410-INFO-product data extraction started....
2025-06-26 00:50:54,457-INFO-product data extraction completed....
2025-06-26 00:50:54,457-INFO-supplier data extraction started....
2025-06-26 00:50:54,511-INFO-supplier data extraction completed....
2025-06-26 00:50:54,511-INFO-inventory data extraction started....
2025-06-26 00:50:54,513-ERROR-Error encounted while extrcting the inventory data file,lxml not found, please install or use the etree parser.
Traceback (most recent call last):
  File "F:\Software Testing\ETL Automation with Python\Project\PythonProject\Capstone_Apr25_Batch_development\CodeBase\extract.py", line 53, in extract_inventory_data_from_file
    df = pd.read_xml("Capstone_Apr25_Batch_development/SourceSystems/inventory_data.xml", xpath=".//item")
         ^^^^^^^^^^^^^^^^^^^^^^^^^^^^^^^^^^^^^^^^^^^^^^^^^^^^^^^^^^^^^^^^^^^^^^^^^^^^^^^^^^^^^^^^^^^^^^^^^
  File "F:\Software Testing\ETL Automation with Python\Project\PythonProject\.venv\Lib\site-packages\pandas\io\xml.py", line 1160, in read_xml
    return _parse(
           ^^^^^^^
  File "F:\Software Testing\ETL Automation with Python\Project\PythonProject\.venv\Lib\site-packages\pandas\io\xml.py", line 830, in _parse
    raise ImportError("lxml not found, please install or use the etree parser.")
ImportError: lxml not found, please install or use the etree parser.
2025-06-26 00:50:54,514-INFO-stores data extraction started....
2025-06-26 00:50:54,606-INFO-stores data extraction completed....
2025-06-26 00:53:48,344-INFO-sales data extraction started....
2025-06-26 00:53:48,689-INFO-sales data extraction completed....
2025-06-26 00:53:48,690-INFO-product data extraction started....
2025-06-26 00:53:48,767-INFO-product data extraction completed....
2025-06-26 00:53:48,767-INFO-supplier data extraction started....
2025-06-26 00:53:48,851-INFO-supplier data extraction completed....
2025-06-26 00:53:48,851-INFO-inventory data extraction started....
2025-06-26 00:53:48,877-ERROR-Error encounted while extrcting the inventory data file,Start tag expected, '<' not found, line 1, column 1 (<string>, line 1)
Traceback (most recent call last):
  File "F:\Software Testing\ETL Automation with Python\Project\PythonProject\Capstone_Apr25_Batch_development\CodeBase\extract.py", line 53, in extract_inventory_data_from_file
    df = pd.read_xml("Capstone_Apr25_Batch_development/SourceSystems/inventory_data.xml", xpath=".//item")
         ^^^^^^^^^^^^^^^^^^^^^^^^^^^^^^^^^^^^^^^^^^^^^^^^^^^^^^^^^^^^^^^^^^^^^^^^^^^^^^^^^^^^^^^^^^^^^^^^^
  File "F:\Software Testing\ETL Automation with Python\Project\PythonProject\.venv\Lib\site-packages\pandas\io\xml.py", line 1160, in read_xml
    return _parse(
           ^^^^^^^
  File "F:\Software Testing\ETL Automation with Python\Project\PythonProject\.venv\Lib\site-packages\pandas\io\xml.py", line 852, in _parse
    data_dicts = p.parse_data()
                 ^^^^^^^^^^^^^^
  File "F:\Software Testing\ETL Automation with Python\Project\PythonProject\.venv\Lib\site-packages\pandas\io\xml.py", line 556, in parse_data
    self.xml_doc = self._parse_doc(self.path_or_buffer)
                   ^^^^^^^^^^^^^^^^^^^^^^^^^^^^^^^^^^^^
  File "F:\Software Testing\ETL Automation with Python\Project\PythonProject\.venv\Lib\site-packages\pandas\io\xml.py", line 647, in _parse_doc
    document = fromstring(
               ^^^^^^^^^^^
  File "src\\lxml\\etree.pyx", line 3307, in lxml.etree.fromstring
  File "src\\lxml\\parser.pxi", line 1995, in lxml.etree._parseMemoryDocument
  File "src\\lxml\\parser.pxi", line 1882, in lxml.etree._parseDoc
  File "src\\lxml\\parser.pxi", line 1164, in lxml.etree._BaseParser._parseDoc
  File "src\\lxml\\parser.pxi", line 633, in lxml.etree._ParserContext._handleParseResultDoc
  File "src\\lxml\\parser.pxi", line 743, in lxml.etree._handleParseResult
  File "src\\lxml\\parser.pxi", line 672, in lxml.etree._raiseParseError
  File "<string>", line 1
lxml.etree.XMLSyntaxError: Start tag expected, '<' not found, line 1, column 1
2025-06-26 00:53:48,902-INFO-stores data extraction started....
2025-06-26 00:53:49,326-INFO-stores data extraction completed....
2025-06-26 00:56:04,601-INFO-sales data extraction started....
2025-06-26 00:56:04,709-INFO-sales data extraction completed....
2025-06-26 00:56:04,709-INFO-product data extraction started....
2025-06-26 00:56:04,765-INFO-product data extraction completed....
2025-06-26 00:56:04,766-INFO-supplier data extraction started....
2025-06-26 00:56:04,826-INFO-supplier data extraction completed....
2025-06-26 00:56:04,826-INFO-inventory data extraction started....
2025-06-26 00:56:04,916-INFO-inventory data extraction completed....
2025-06-26 00:56:04,916-INFO-stores data extraction started....
2025-06-26 00:56:05,008-INFO-stores data extraction completed....
2025-06-26 01:00:14,349-INFO-sales data extraction started....
2025-06-26 01:00:14,495-INFO-sales data extraction completed....
2025-06-26 01:00:14,496-INFO-product data extraction started....
2025-06-26 01:00:14,584-INFO-product data extraction completed....
2025-06-26 01:00:14,584-INFO-supplier data extraction started....
2025-06-26 01:00:14,705-INFO-supplier data extraction completed....
2025-06-26 01:00:14,705-INFO-inventory data extraction started....
2025-06-26 01:00:14,991-INFO-inventory data extraction completed....
2025-06-26 01:00:14,991-INFO-stores data extraction started....
2025-06-26 01:00:15,241-INFO-stores data extraction completed....
=======
2025-06-27 19:38:04,031-INFO-Data Load started ....
2025-06-27 19:38:04,065-INFO-fact_sales table started loading...
2025-06-27 19:38:04,065-INFO-
        INSERT INTO retaildwh.fact_sales (sales_id, product_id, store_id, quantity, total_sales, sale_date)
        SELECT sales_id, product_id, store_id, quantity, total_sales, sale_date
        FROM stag_retaildwg.sales_with_details
    
2025-06-27 19:38:04,065-INFO-Rows inserted: 42
2025-06-27 19:38:04,065-INFO-fact_sales table completed loading...
2025-06-27 19:38:04,079-INFO-Data Load completed ....
2025-06-27 19:40:21,990-INFO-sales data extraction started....
2025-06-27 19:40:22,212-INFO-sales data extraction completed....
2025-06-27 19:40:27,806-INFO-Data Transformation started ....
2025-06-27 19:40:27,806-INFO-transform_filter_sales_data started....
2025-06-27 19:40:27,863-INFO-transform_router_sales_data started....
2025-06-27 19:40:27,879-INFO-transform_aggregator_sales_data started....
2025-06-27 19:40:27,886-INFO-transform_aggregator_inventory_data started....
2025-06-27 19:40:27,911-INFO-transform_joiner_sales_products_stores_data started....
2025-06-27 19:40:27,911-INFO-Data Transformation finished ....
2025-06-27 19:44:28,006-INFO-sales data extraction started....
2025-06-27 19:44:28,117-INFO-sales data extraction completed....
2025-06-27 19:45:50,420-INFO-sales data extraction started....
2025-06-27 19:45:50,516-INFO-sales data extraction completed....
2025-06-27 19:45:50,532-INFO-product data extraction started....
2025-06-27 19:45:50,596-INFO-product data extraction completed....
2025-06-27 19:45:50,596-INFO-supplier data extraction started....
2025-06-27 19:45:50,676-INFO-supplier data extraction completed....
2025-06-27 19:45:50,676-INFO-inventory data extraction started....
2025-06-27 19:45:50,892-INFO-inventory data extraction completed....
2025-06-27 19:45:50,892-INFO-stores data extraction started....
2025-06-27 19:45:52,044-INFO-stores data extraction completed....
2025-06-27 19:45:59,053-INFO-Data Transformation started ....
2025-06-27 19:45:59,053-INFO-transform_filter_sales_data started....
2025-06-27 19:45:59,133-INFO-transform_filter_sales_data completed....
2025-06-27 19:45:59,133-INFO-transform_router_sales_data started....
2025-06-27 19:45:59,261-INFO-transform_router_sales_data completed....
2025-06-27 19:45:59,261-INFO-transform_aggregator_sales_data started....
2025-06-27 19:45:59,341-INFO-transform_aggregator_sales_data completed....
2025-06-27 19:45:59,341-INFO-transform_aggregator_inventory_data started....
2025-06-27 19:45:59,533-INFO-transform_aggregator_inventory_data completed....
2025-06-27 19:45:59,533-INFO-transform_joiner_sales_products_stores_data started....
2025-06-27 19:45:59,629-INFO-transform_joiner_sales_products_stores_data completed....
2025-06-27 19:45:59,629-INFO-Data Transformation finished ....
2025-06-27 19:46:05,127-INFO-Data Load started ....
2025-06-27 19:46:05,148-INFO-fact_sales table started loading...
2025-06-27 19:46:05,148-INFO-
        INSERT INTO retaildwh.fact_sales (sales_id, product_id, store_id, quantity, total_sales, sale_date)
        SELECT sales_id, product_id, store_id, quantity, total_sales, sale_date
        FROM stag_retaildwg.sales_with_details
    
2025-06-27 19:46:05,148-INFO-Rows inserted: 42
2025-06-27 19:46:05,148-INFO-fact_sales table completed loading...
2025-06-27 19:46:05,162-INFO-Data Load completed ....
2025-06-27 19:47:46,524-INFO-Data Load started ....
2025-06-27 19:47:46,524-INFO-fact_sales table started loading...
2025-06-27 19:47:46,524-INFO-
        INSERT INTO retaildwh.fact_sales (sales_id, product_id, store_id, quantity, total_sales, sale_date)
        SELECT sales_id, product_id, store_id, quantity, total_sales, sale_date
        FROM stag_retaildwg.sales_with_details
    
2025-06-27 19:47:46,541-INFO-Rows inserted: 42
2025-06-27 19:47:46,541-INFO-fact_sales table completed loading...
2025-06-27 19:47:46,588-INFO-Data Load completed ....
>>>>>>> 6d874cd3ddababf58aa9b8ae64039ef4599491f7
2025-06-27 22:30:45,253-INFO-Data Transformation started ....
2025-06-27 22:30:45,280-INFO-transform_filter_sales_data started....
2025-06-27 22:30:46,019-INFO-transform_filter_sales_data completed....
2025-06-27 22:30:46,019-INFO-transform_router_sales_data started....
2025-06-27 22:30:46,142-INFO-transform_router_sales_data completed....
2025-06-27 22:30:46,143-INFO-transform_aggregator_sales_data started....
2025-06-27 22:30:46,211-INFO-transform_aggregator_sales_data completed....
2025-06-27 22:30:46,211-INFO-transform_aggregator_inventory_data started....
2025-06-27 22:30:46,262-INFO-transform_aggregator_inventory_data completed....
2025-06-27 22:30:46,262-INFO-transform_joiner_sales_products_stores_data started....
2025-06-27 22:30:46,385-INFO-transform_joiner_sales_products_stores_data completed....
2025-06-27 22:30:46,385-INFO-Data Transformation finished ....
2025-06-27 23:01:52,406-INFO-Data Load started ....
2025-06-27 23:01:52,532-INFO-fact_sales table started loading...
2025-06-27 23:01:52,533-INFO-
        INSERT INTO retaildwh.fact_sales (sales_id, product_id, store_id, quantity, total_sales, sale_date)
        SELECT sales_id, product_id, store_id, quantity, total_sales, sale_date
        FROM stag_retaildwg.sales_with_details
    
2025-06-27 23:01:52,561-ERROR-Error encountered while loading into fact_sales: (pymysql.err.OperationalError) (1049, "Unknown database 'stag_retaildwg'")
[SQL: 
        INSERT INTO retaildwh.fact_sales (sales_id, product_id, store_id, quantity, total_sales, sale_date)
        SELECT sales_id, product_id, store_id, quantity, total_sales, sale_date
        FROM stag_retaildwg.sales_with_details
    ]
(Background on this error at: https://sqlalche.me/e/20/e3q8)
Traceback (most recent call last):
  File "F:\Software Testing\ETL Automation with Python\Project\PythonProject\.venv\Lib\site-packages\sqlalchemy\engine\base.py", line 1963, in _exec_single_context
    self.dialect.do_execute(
  File "F:\Software Testing\ETL Automation with Python\Project\PythonProject\.venv\Lib\site-packages\sqlalchemy\engine\default.py", line 943, in do_execute
    cursor.execute(statement, parameters)
  File "F:\Software Testing\ETL Automation with Python\Project\PythonProject\.venv\Lib\site-packages\pymysql\cursors.py", line 153, in execute
    result = self._query(query)
             ^^^^^^^^^^^^^^^^^^
  File "F:\Software Testing\ETL Automation with Python\Project\PythonProject\.venv\Lib\site-packages\pymysql\cursors.py", line 322, in _query
    conn.query(q)
  File "F:\Software Testing\ETL Automation with Python\Project\PythonProject\.venv\Lib\site-packages\pymysql\connections.py", line 563, in query
    self._affected_rows = self._read_query_result(unbuffered=unbuffered)
                          ^^^^^^^^^^^^^^^^^^^^^^^^^^^^^^^^^^^^^^^^^^^^^^
  File "F:\Software Testing\ETL Automation with Python\Project\PythonProject\.venv\Lib\site-packages\pymysql\connections.py", line 825, in _read_query_result
    result.read()
  File "F:\Software Testing\ETL Automation with Python\Project\PythonProject\.venv\Lib\site-packages\pymysql\connections.py", line 1199, in read
    first_packet = self.connection._read_packet()
                   ^^^^^^^^^^^^^^^^^^^^^^^^^^^^^^
  File "F:\Software Testing\ETL Automation with Python\Project\PythonProject\.venv\Lib\site-packages\pymysql\connections.py", line 775, in _read_packet
    packet.raise_for_error()
  File "F:\Software Testing\ETL Automation with Python\Project\PythonProject\.venv\Lib\site-packages\pymysql\protocol.py", line 219, in raise_for_error
    err.raise_mysql_exception(self._data)
  File "F:\Software Testing\ETL Automation with Python\Project\PythonProject\.venv\Lib\site-packages\pymysql\err.py", line 150, in raise_mysql_exception
    raise errorclass(errno, errval)
pymysql.err.OperationalError: (1049, "Unknown database 'stag_retaildwg'")

The above exception was the direct cause of the following exception:

Traceback (most recent call last):
  File "F:\Software Testing\ETL Automation with Python\Project\PythonProject\Capstone_Pipeline_Extract_Dev\CodeBase\load.py", line 26, in load_fact_sales_table
    result = conn.execute(query)
             ^^^^^^^^^^^^^^^^^^^
  File "F:\Software Testing\ETL Automation with Python\Project\PythonProject\.venv\Lib\site-packages\sqlalchemy\engine\base.py", line 1415, in execute
    return meth(
           ^^^^^
  File "F:\Software Testing\ETL Automation with Python\Project\PythonProject\.venv\Lib\site-packages\sqlalchemy\sql\elements.py", line 523, in _execute_on_connection
    return connection._execute_clauseelement(
           ^^^^^^^^^^^^^^^^^^^^^^^^^^^^^^^^^^
  File "F:\Software Testing\ETL Automation with Python\Project\PythonProject\.venv\Lib\site-packages\sqlalchemy\engine\base.py", line 1637, in _execute_clauseelement
    ret = self._execute_context(
          ^^^^^^^^^^^^^^^^^^^^^^
  File "F:\Software Testing\ETL Automation with Python\Project\PythonProject\.venv\Lib\site-packages\sqlalchemy\engine\base.py", line 1842, in _execute_context
    return self._exec_single_context(
           ^^^^^^^^^^^^^^^^^^^^^^^^^^
  File "F:\Software Testing\ETL Automation with Python\Project\PythonProject\.venv\Lib\site-packages\sqlalchemy\engine\base.py", line 1982, in _exec_single_context
    self._handle_dbapi_exception(
  File "F:\Software Testing\ETL Automation with Python\Project\PythonProject\.venv\Lib\site-packages\sqlalchemy\engine\base.py", line 2351, in _handle_dbapi_exception
    raise sqlalchemy_exception.with_traceback(exc_info[2]) from e
  File "F:\Software Testing\ETL Automation with Python\Project\PythonProject\.venv\Lib\site-packages\sqlalchemy\engine\base.py", line 1963, in _exec_single_context
    self.dialect.do_execute(
  File "F:\Software Testing\ETL Automation with Python\Project\PythonProject\.venv\Lib\site-packages\sqlalchemy\engine\default.py", line 943, in do_execute
    cursor.execute(statement, parameters)
  File "F:\Software Testing\ETL Automation with Python\Project\PythonProject\.venv\Lib\site-packages\pymysql\cursors.py", line 153, in execute
    result = self._query(query)
             ^^^^^^^^^^^^^^^^^^
  File "F:\Software Testing\ETL Automation with Python\Project\PythonProject\.venv\Lib\site-packages\pymysql\cursors.py", line 322, in _query
    conn.query(q)
  File "F:\Software Testing\ETL Automation with Python\Project\PythonProject\.venv\Lib\site-packages\pymysql\connections.py", line 563, in query
    self._affected_rows = self._read_query_result(unbuffered=unbuffered)
                          ^^^^^^^^^^^^^^^^^^^^^^^^^^^^^^^^^^^^^^^^^^^^^^
  File "F:\Software Testing\ETL Automation with Python\Project\PythonProject\.venv\Lib\site-packages\pymysql\connections.py", line 825, in _read_query_result
    result.read()
  File "F:\Software Testing\ETL Automation with Python\Project\PythonProject\.venv\Lib\site-packages\pymysql\connections.py", line 1199, in read
    first_packet = self.connection._read_packet()
                   ^^^^^^^^^^^^^^^^^^^^^^^^^^^^^^
  File "F:\Software Testing\ETL Automation with Python\Project\PythonProject\.venv\Lib\site-packages\pymysql\connections.py", line 775, in _read_packet
    packet.raise_for_error()
  File "F:\Software Testing\ETL Automation with Python\Project\PythonProject\.venv\Lib\site-packages\pymysql\protocol.py", line 219, in raise_for_error
    err.raise_mysql_exception(self._data)
  File "F:\Software Testing\ETL Automation with Python\Project\PythonProject\.venv\Lib\site-packages\pymysql\err.py", line 150, in raise_mysql_exception
    raise errorclass(errno, errval)
sqlalchemy.exc.OperationalError: (pymysql.err.OperationalError) (1049, "Unknown database 'stag_retaildwg'")
[SQL: 
        INSERT INTO retaildwh.fact_sales (sales_id, product_id, store_id, quantity, total_sales, sale_date)
        SELECT sales_id, product_id, store_id, quantity, total_sales, sale_date
        FROM stag_retaildwg.sales_with_details
    ]
(Background on this error at: https://sqlalche.me/e/20/e3q8)
2025-06-27 23:01:52,743-INFO-fact_inventory table started loading...
2025-06-27 23:01:52,743-INFO-
        INSERT INTO retaildwh.fact_inventory (product_id, store_id, quantity_on_hand, last_updated)
        SELECT product_id, store_id, quantity_on_hand, last_updated
        FROM stag_retaildwh.staging_inventory
    
2025-06-27 23:01:52,775-INFO-Rows inserted: 30
2025-06-27 23:01:52,775-INFO-fact_inventory table completed loading...
2025-06-27 23:01:52,789-INFO-inventory_levels_by_store table started loading...
2025-06-27 23:01:52,789-INFO-
        INSERT INTO retaildwh.inventory_levels_by_store (store_id, total_inventory)
        SELECT store_id, total_inventory
        FROM stag_retaildwh.aggregated_inventory_level
    
2025-06-27 23:01:52,796-INFO-Rows inserted: 10
2025-06-27 23:01:52,796-INFO-inventory_levels_by_store table completed loading...
2025-06-27 23:01:52,800-INFO-monthly_sales_summary table started loading...
2025-06-27 23:01:52,800-INFO-
        INSERT INTO retaildwh.monthly_sales_summary (product_id, month, year, total_sales)
        SELECT product_id, month, year, total_sales
        FROM stag_retaildwh.monthly_sales_summary_source
    
2025-06-27 23:01:52,806-INFO-Rows inserted: 20
2025-06-27 23:01:52,806-INFO-monthly_sales_summary table completed loading...
2025-06-27 23:01:52,811-INFO-Data Load completed ....
2025-06-27 23:05:57,227-INFO-Data Load started ....
2025-06-27 23:05:57,263-INFO-fact_sales table started loading...
2025-06-27 23:05:57,263-INFO-
        INSERT INTO retaildwh.fact_sales (sales_id, product_id, store_id, quantity, total_sales, sale_date)
        SELECT sales_id, product_id, store_id, quantity, total_sales, sale_date
        FROM stag_retaildwh.sales_with_details
    
2025-06-27 23:05:57,292-INFO-Rows inserted: 42
2025-06-27 23:05:57,292-INFO-fact_sales table completed loading...
2025-06-27 23:05:57,297-INFO-fact_inventory table started loading...
2025-06-27 23:05:57,297-INFO-
        INSERT INTO retaildwh.fact_inventory (product_id, store_id, quantity_on_hand, last_updated)
        SELECT product_id, store_id, quantity_on_hand, last_updated
        FROM stag_retaildwh.staging_inventory
    
2025-06-27 23:05:57,303-INFO-Rows inserted: 30
2025-06-27 23:05:57,303-INFO-fact_inventory table completed loading...
2025-06-27 23:05:57,309-INFO-inventory_levels_by_store table started loading...
2025-06-27 23:05:57,309-INFO-
        INSERT INTO retaildwh.inventory_levels_by_store (store_id, total_inventory)
        SELECT store_id, total_inventory
        FROM stag_retaildwh.aggregated_inventory_level
    
2025-06-27 23:05:57,314-INFO-Rows inserted: 10
2025-06-27 23:05:57,314-INFO-inventory_levels_by_store table completed loading...
2025-06-27 23:05:57,319-INFO-monthly_sales_summary table started loading...
2025-06-27 23:05:57,320-INFO-
        INSERT INTO retaildwh.monthly_sales_summary (product_id, month, year, total_sales)
        SELECT product_id, month, year, total_sales
        FROM stag_retaildwh.monthly_sales_summary_source
    
2025-06-27 23:05:57,324-INFO-Rows inserted: 20
2025-06-27 23:05:57,325-INFO-monthly_sales_summary table completed loading...
2025-06-27 23:05:57,328-INFO-Data Load completed ....
